Lmod has detected the following error: The following module(s) are unknown:
".~/TVB/virtual_aging_brain/env/bin/activate"

Please check the spelling or version number. Also try "module spider ..."
It is also possible your cache file is out-of-date; it may help to try:
  $ module --ignore_cache load ".~/TVB/virtual_aging_brain/env/bin/activate"

Also make sure that all modulefiles written in TCL start with the string
#%Module



Processing subject: sub-0001
Traceback (most recent call last):
  File "/home/jneudorf/TVB/virtual_aging_brain/env/lib/python3.7/site-packages/pandas/core/indexes/base.py", line 3361, in get_loc
    return self._engine.get_loc(casted_key)
  File "pandas/_libs/index.pyx", line 76, in pandas._libs.index.IndexEngine.get_loc
  File "pandas/_libs/index.pyx", line 108, in pandas._libs.index.IndexEngine.get_loc
  File "pandas/_libs/hashtable_class_helper.pxi", line 5198, in pandas._libs.hashtable.PyObjectHashTable.get_item
  File "pandas/_libs/hashtable_class_helper.pxi", line 5206, in pandas._libs.hashtable.PyObjectHashTable.get_item
KeyError: 'FCD_rank'

The above exception was the direct cause of the following exception:

Traceback (most recent call last):
  File "heatmap.py", line 34, in <module>
    data_tmp['RCD_rank'] = data_tmp['FCD_rank'].rank(na_option='top')
  File "/home/jneudorf/TVB/virtual_aging_brain/env/lib/python3.7/site-packages/pandas/core/frame.py", line 3458, in __getitem__
    indexer = self.columns.get_loc(key)
  File "/home/jneudorf/TVB/virtual_aging_brain/env/lib/python3.7/site-packages/pandas/core/indexes/base.py", line 3363, in get_loc
    raise KeyError(key) from err
KeyError: 'FCD_rank'
